<?xml version="1.0"?>
<robot xmlns:xacro="http://www.ros.org/wiki/xacro">

  <!-- Include Utilities -->
  <xacro:include filename="$(find description)/utilities.xacro" />

  <!-- some parameters -->
  <xacro:property name="safety" value="true"/>

  <!-- some constants -->
  <xacro:property name="safety_controller_k_pos" value="100"/>
  <xacro:property name="safety_controller_k_vel" value="10"/>
  <xacro:property name="safety_percentage" value="0.95"/>
  <xacro:property name="joint_damping" value="0.5"/>
  <!-- joint limits -->
  <xacro:property name="joint_limit_1" value="170"/>
  <xacro:property name="joint_limit_2" value="120"/>
  <xacro:property name="joint_limit_3" value="170"/>
  <xacro:property name="joint_limit_4" value="120"/>
  <xacro:property name="joint_limit_5" value="170"/>
  <xacro:property name="joint_limit_6" value="120"/>
  <xacro:property name="joint_limit_7" value="175"/>
  <!-- max torques per joint -->
  <xacro:property name="max_effort_1" value="176"/>
  <xacro:property name="max_effort_2" value="176"/>
  <xacro:property name="max_effort_3" value="110"/>
  <xacro:property name="max_effort_4" value="110"/>
  <xacro:property name="max_effort_5" value="110"/>
  <xacro:property name="max_effort_6" value="40"/>
  <xacro:property name="max_effort_7" value="40"/>
  <!-- max velocities per joint -->
  <xacro:property name="max_velocity_1" value="${98 * PI / 180.}"/>
  <xacro:property name="max_velocity_2" value="${98 * PI / 180.}"/>
  <xacro:property name="max_velocity_3" value="${100 * PI / 180.}"/>
  <xacro:property name="max_velocity_4" value="${130 * PI / 180.}"/>
  <xacro:property name="max_velocity_5" value="${140 * PI / 180.}"/>
  <xacro:property name="max_velocity_6" value="${PI}"/>
  <xacro:property name="max_velocity_7" value="${PI}"/>

  <xacro:macro name="iiwa7" params="parent hardware_interface robot_name collision_postfix *origin">

    <!--joint between {parent} and link_0-->
    <joint name="${parent}_${robot_name}_joint" type="fixed">
      <xacro:insert_block name="origin"/>
      <parent link="${parent}"/>
      <child link="${robot_name}_link_0"/>
    </joint>

    <link name="${robot_name}_link_0">
      <inertial>
        <origin xyz="-0.1 0 0.07" rpy="0 0 0"/>
        <mass value="5"/>
        <inertia ixx="0.05"  ixy="0"  ixz="0" iyy="0.06" iyz="0" izz="0.03" />
      </inertial>

      <visual>
        <origin xyz="0 0 0" rpy="0 0 0"/>
        <geometry>
          <mesh filename="package://simmulator/meshes/iiwa7/visual/link_0.stl"/>
        </geometry>
        <material name="Grey"/>
      </visual>

      <collision>
        <origin xyz="0 0 0" rpy="0 0 0"/>
        <geometry>
          <mesh filename="package://simmulator/meshes/iiwa7/collision/link_0.stl"/>
        </geometry>
        <material name="Grey"/>
      </collision>

      <self_collision_checking>
        <origin xyz="0 0 0" rpy="0 0 0"/>
        <geometry>
          <capsule radius="0.15" length="0.25"/>
        </geometry>
      </self_collision_checking>

    </link>

    <!-- joint between link_0 and link_1 -->
    <joint name="${robot_name}_joint_1" type="revolute">
      <parent link="${robot_name}_link_0"/>
      <child link="${robot_name}_link_1"/>
      <origin xyz="0 0 0.15" rpy="0 0 0"/>
      <axis xyz="0 0 1"/>
      <limit lower="${-joint_limit_1 * PI / 180}" upper="${joint_limit_1 * PI / 180}"
             effort="${max_effort_1}" velocity="${max_velocity_1}" />
      <xacro:safe_controller safety="${safety}"
                             lower="${-safety_percentage * joint_limit_1 * PI / 180}"
                             upper="${safety_percentage * joint_limit_1 * PI / 180}"
                             k_p="${safety_controller_k_pos}"
                             k_v="${safety_controller_k_vel}"/>
      <dynamics damping="${joint_damping}"/>
    </joint>

    <link name="${robot_name}_link_1">
      <inertial>
        <origin xyz="0 -0.03 0.12" rpy="0 0 0"/>
        <mass value="3.4525"/>
        <inertia ixx="0.02183"  ixy="0"  ixz="0" iyy="0.007703" iyz="-0.003887" izz="0.02083" />
      </inertial>
      <visual>
        <origin xyz="0 0 0.0075" rpy="0 0 0"/>
        <geometry>
          <mesh filename="package://simmulator/meshes/iiwa7/visual/link_1.stl"/>
        </geometry>
        <material name="Orange"/>
      </visual>
      <collision>
        <origin xyz="0 0 0.0075" rpy="0 0 0"/>
        <geometry>
          <mesh filename="package://simmulator/meshes/iiwa7/collision/link_1.stl"/>
        </geometry>
        <material name="Orange"/>
      </collision>
    </link>

    <joint name="${robot_name}_joint_2" type="revolute">
      <parent link="${robot_name}_link_1"/>
      <child link="${robot_name}_link_2"/>
      <origin xyz="0 0 0.19" rpy="${PI / 2} 0 ${PI}"/>
      <axis xyz="0 0 1"/>
      <limit lower="${-joint_limit_2 * PI / 180}" upper="${joint_limit_2 * PI / 180}"
             effort="${max_effort_2}" velocity="${max_velocity_2}" />
      <xacro:safe_controller safety="${safety}"
                             lower="${-safety_percentage * joint_limit_2 * PI / 180}"
                             upper="${safety_percentage * joint_limit_2 * PI / 180}"
                             k_p="${safety_controller_k_pos}"
                             k_v="${safety_controller_k_vel}"/>
      <dynamics damping="${joint_damping}"/>
    </joint>

    <link name="${robot_name}_link_2">
      <inertial>
        <origin xyz="0.0003 0.059 0.042" rpy="0 0 0"/>
        <mass value="3.4821"/>
        <inertia ixx="0.02076"  ixy="0"  ixz="-0.003626" iyy="0.02179" iyz="0" izz="0.00779" />
      </inertial>
      <visual>
        <origin xyz="0 0 0" rpy="0 0 0"/>
        <geometry>
          <mesh filename="package://simmulator/meshes/iiwa7/visual/link_2.stl"/>
        </geometry>
        <material name="Orange"/>
      </visual>

      <collision>
        <origin xyz="0 0 0" rpy="0 0 0"/>
        <geometry>
          <mesh filename="package://simmulator/meshes/iiwa7/collision/link_2.stl"/>
        </geometry>
        <material name="Orange"/>
      </collision>
    </link>
  </xacro:macro>
</robot>
