<sdf version='1.7'>
  <world name='default'>
    <light name='sun' type='directional'>
      <cast_shadows>1</cast_shadows>
      <pose>0 0 10 0 -0 0</pose>
      <diffuse>0.8 0.8 0.8 1</diffuse>
      <specular>0.2 0.2 0.2 1</specular>
      <attenuation>
        <range>1000</range>
        <constant>0.9</constant>
        <linear>0.01</linear>
        <quadratic>0.001</quadratic>
      </attenuation>
      <direction>-0.5 0.1 -0.9</direction>
      <spot>
        <inner_angle>0</inner_angle>
        <outer_angle>0</outer_angle>
        <falloff>0</falloff>
      </spot>
    </light>
    <model name='ground_plane'>
      <static>1</static>
      <link name='link'>
      <collision name='collision'>
        <geometry>
          <plane>
            <normal>0 0 1</normal>
            <size>100 100</size>
          </plane>
        </geometry>
        <surface>
          <contact>
            <collide_bitmask>65535</collide_bitmask>
            <ode />
          </contact>
          <friction>
            <ode>
              <mu>100</mu>
              <mu2>50</mu2>
            </ode>
            <torsional>
              <ode />
            </torsional>
          </friction>
          <bounce />
        </surface>
        <max_contacts>10</max_contacts>
      </collision>
      <visual name='visual'>
        <cast_shadows>0</cast_shadows>
        <geometry>
          <plane>
            <normal>0 0 1</normal>
            <size>100 100</size>
          </plane>
        </geometry>
        <material>
          <script>
              <uri>file://media/materials/scripts/gazebo.material</uri>
              <name>Gazebo/Grey</name>
          </script>
        </material>
      </visual>
      <self_collide>0</self_collide>
      <enable_wind>0</enable_wind>
      <kinematic>0</kinematic>
      </link>
    </model>
    <gravity>0 0 -9.8</gravity>
    <magnetic_field>6e-06 2.3e-05 -4.2e-05</magnetic_field>
    <atmosphere type='adiabatic' />
    <physics type='ode'>
      <max_step_size>0.001</max_step_size>
      <real_time_factor>1</real_time_factor>
      <real_time_update_rate>1000</real_time_update_rate>
    </physics>
    <scene>
      <ambient>0.4 0.4 0.4 1</ambient>
      <background>0.7 0.7 0.7 1</background>
      <shadows>1</shadows>
    </scene>
    <audio>
      <device>default</device>
    </audio>
    <wind />
    <spherical_coordinates>
      <surface_model>EARTH_WGS84</surface_model>
      <latitude_deg>0</latitude_deg>
      <longitude_deg>0</longitude_deg>
      <elevation>0</elevation>
      <heading_deg>0</heading_deg>
    </spherical_coordinates>
    <model name='bot'>
      <joint name='world_iiwa_joint' type='fixed'>
        <pose relative_to='__model__'>0 0 0 0 -0 0</pose>
        <parent>world</parent>
        <child>iiwa_link_0</child>
      </joint>
      <link name='iiwa_link_0'>
      <pose relative_to='world_iiwa_joint'>0 0 0 0 -0 0</pose>
      <inertial>
        <pose>-0.1 0 0.07 0 -0 0</pose>
        <mass>5</mass>
        <inertia>
          <ixx>0.05</ixx>
          <ixy>0</ixy>
          <ixz>0</ixz>
          <iyy>0.06</iyy>
          <iyz>0</iyz>
          <izz>0.03</izz>
        </inertia>
      </inertial>
      <collision name='iiwa_link_0_collision'>
        <pose>0 0 0 0 -0 0</pose>
        <geometry>
          <mesh>
            <scale>1 1 1</scale>
            <uri>
              /home/aaditya/Intro-to-robotics/ass1/ros2_ws/install/simmulator/share/simmulator/meshes/iiwa7/collision/link_0.stl
            </uri>
          </mesh>
        </geometry>
        <max_contacts>10</max_contacts>
        <surface>
          <contact>
            <ode />
          </contact>
          <bounce />
          <friction>
            <torsional>
              <ode />
            </torsional>
            <ode />
          </friction>
        </surface>
      </collision>
      <visual name='iiwa_link_0_visual'>
        <pose>0 0 0 0 -0 0</pose>
        <geometry>
          <mesh>
            <scale>1 1 1</scale>
            <uri>
              /home/aaditya/Intro-to-robotics/ass1/ros2_ws/install/simmulator/share/simmulator/meshes/iiwa7/visual/link_0.stl
            </uri>
          </mesh>
        </geometry>
      </visual>
      <self_collide>0</self_collide>
      <enable_wind>0</enable_wind>
      <kinematic>0</kinematic>
      </link>
      <joint name='iiwa_joint_1' type='revolute'>
        <pose relative_to='iiwa_link_0'>0 0 0.15 0 -0 0</pose>
        <parent>iiwa_link_0</parent>
        <child>iiwa_link_1</child>
        <axis>
          <xyz>0 0 1</xyz>
          <limit>
            <lower>-2.96706</lower>
            <upper>2.96706</upper>
            <effort>176</effort>
            <velocity>1.71042</velocity>
          </limit>
          <dynamics>
            <damping>0.5</damping>
            <friction>0</friction>
            <spring_reference>0</spring_reference>
            <spring_stiffness>0</spring_stiffness>
          </dynamics>
        </axis>
      </joint>
      <link name='iiwa_link_1'>
      <pose relative_to='iiwa_joint_1'>0 0 0 0 -0 0</pose>
      <inertial>
        <pose>0 -0.03 0.12 0 -0 0</pose>
        <mass>3.4525</mass>
        <inertia>
          <ixx>0.02183</ixx>
          <ixy>0</ixy>
          <ixz>0</ixz>
          <iyy>0.007703</iyy>
          <iyz>-0.003887</iyz>
          <izz>0.02083</izz>
        </inertia>
      </inertial>
      <collision name='iiwa_link_1_collision'>
        <pose>0 0 0.0075 0 -0 0</pose>
        <geometry>
          <mesh>
            <scale>1 1 1</scale>
            <uri>
              /home/aaditya/Intro-to-robotics/ass1/ros2_ws/install/simmulator/share/simmulator/meshes/iiwa7/collision/link_1.stl
            </uri>
          </mesh>
        </geometry>
        <max_contacts>10</max_contacts>
        <surface>
          <contact>
            <ode />
          </contact>
          <bounce />
          <friction>
            <torsional>
              <ode />
            </torsional>
            <ode />
          </friction>
        </surface>
      </collision>
      <visual name='iiwa_link_1_visual'>
        <pose>0 0 0.0075 0 -0 0</pose>
        <geometry>
          <mesh>
            <scale>1 1 1</scale>
            <uri>
              /home/aaditya/Intro-to-robotics/ass1/ros2_ws/install/simmulator/share/simmulator/meshes/iiwa7/visual/link_1.stl
            </uri>
          </mesh>
        </geometry>
      </visual>
      <self_collide>0</self_collide>
      <enable_wind>0</enable_wind>
      <kinematic>0</kinematic>
      </link>
      <joint name='iiwa_joint_2' type='revolute'>
        <pose relative_to='iiwa_link_1'>0 0 0.19 1.5708 -0 3.14159</pose>
        <parent>iiwa_link_1</parent>
        <child>iiwa_link_2</child>
        <axis>
          <xyz>0 0 1</xyz>
          <limit>
            <lower>-2.0944</lower>
            <upper>2.0944</upper>
            <effort>176</effort>
            <velocity>1.71042</velocity>
          </limit>
          <dynamics>
            <damping>0.5</damping>
            <friction>0</friction>
            <spring_reference>0</spring_reference>
            <spring_stiffness>0</spring_stiffness>
          </dynamics>
        </axis>
      </joint>
      <link name='iiwa_link_2'>
      <pose relative_to='iiwa_joint_2'>0 0 0 0 -0 0</pose>
      <inertial>
        <pose>0.0003 0.059 0.042 0 -0 0</pose>
        <mass>3.4821</mass>
        <inertia>
          <ixx>0.02076</ixx>
          <ixy>0</ixy>
          <ixz>-0.003626</ixz>
          <iyy>0.02179</iyy>
          <iyz>0</iyz>
          <izz>0.00779</izz>
        </inertia>
      </inertial>
      <collision name='iiwa_link_2_collision'>
        <pose>0 0 0 0 -0 0</pose>
        <geometry>
          <mesh>
            <scale>1 1 1</scale>
            <uri>
              /home/aaditya/Intro-to-robotics/ass1/ros2_ws/install/simmulator/share/simmulator/meshes/iiwa7/collision/link_2.stl
            </uri>
          </mesh>
        </geometry>
        <max_contacts>10</max_contacts>
        <surface>
          <contact>
            <ode />
          </contact>
          <bounce />
          <friction>
            <torsional>
              <ode />
            </torsional>
            <ode />
          </friction>
        </surface>
      </collision>
      <visual name='iiwa_link_2_visual'>
        <pose>0 0 0 0 -0 0</pose>
        <geometry>
          <mesh>
            <scale>1 1 1</scale>
            <uri>
              /home/aaditya/Intro-to-robotics/ass1/ros2_ws/install/simmulator/share/simmulator/meshes/iiwa7/visual/link_2.stl
            </uri>
          </mesh>
        </geometry>
      </visual>
      <self_collide>0</self_collide>
      <enable_wind>0</enable_wind>
      <kinematic>0</kinematic>
      </link>
      <pose>0 0 0 0 -0 0</pose>
    </model>
    <state world_name='default'>
      <sim_time>394 800000000</sim_time>
      <real_time>396 30573461</real_time>
      <wall_time>1723133388 398325450</wall_time>
      <iterations>394800</iterations>
      <model name='bot'>
        <pose>0 0 0 0 -1e-06 0</pose>
        <scale>1 1 1</scale>
        <link name='iiwa_link_0'>
        <pose>0 0 0 0 -1e-06 0</pose>
        <velocity>-1e-06 -1e-06 -9.4e-05 -2.2e-05 0.000355 3e-06</velocity>
        <acceleration>0.046879 0.001388 -0.116668 -0.043671 0.710407 0.005008</acceleration>
        <wrench>0.234395 0.006941 -0.583341 0 -0 0</wrench>
        </link>
        <link name='iiwa_link_1'>
        <pose>-0 0 0.15 -0 -2e-06 0.000676</pose>
        <velocity>3.4e-05 -1e-06 -0.000104 -2.3e-05 0.000464 0.000117</velocity>
        <acceleration>0.186708 0.002723 -0.207099 -0.046085 0.928923 0.230607</acceleration>
        <wrench>0.644608 0.009401 -0.71501 0 -0 0</wrench>
        </link>
        <link name='iiwa_link_2'>
        <pose>-1e-06 0 0.34 -1.5708 1.04719 0.000667</pose>
        <velocity>0.000121 2e-06 -0.000104 -1.9e-05 0.000454 0.000119</velocity>
        <acceleration>0.204179 -0.009057 -0.163177 -2.9842 0.433834 2.82687</acceleration>
        <wrench>0.710973 -0.031537 -0.5682 0 -0 0</wrench>
        </link>
      </model>
      <model name='ground_plane'>
        <pose>0 0 0 0 -0 0</pose>
        <scale>1 1 1</scale>
        <link name='link'>
        <pose>0 0 0 0 -0 0</pose>
        <velocity>0 0 0 0 -0 0</velocity>
        <acceleration>0 0 0 0 -0 0</acceleration>
        <wrench>0 0 0 0 -0 0</wrench>
        </link>
      </model>
      <light name='sun'>
        <pose>0 0 10 0 -0 0</pose>
      </light>
    </state>
    <gui fullscreen='0'>
      <camera name='user_camera'>
        <pose>0.669054 -1.0478 0.70841 0 0.421914 2.18397</pose>
        <view_controller>orbit</view_controller>
        <projection_type>perspective</projection_type>
      </camera>
    </gui>
  </world>
</sdf>